zloganalyzer: Critical error, Induced data error 
 - exiting application
Stack trace: 
Traceback (most recent call last):
  File "BASE_DIR/loganalyzer/systest/localtests/systesterrormsgtouser.py", line 69, in test_datasrc_error_running_app_as_in_verbose_mode
    app.run()
  File "BASE_DIR/loganalyzer/loganalyzercli.py", line 94, in run
    app.run()
  File "BASE_DIR/loganalyzer/application.py", line 18, in run
    for data in self.datasource.get_data():
  File EXTERNAL_SOURCE, in __call__
    return _mock_self._mock_call(*args, **kwargs)
  File EXTERNAL_SOURCE, in _mock_call
    raise effect
loganalyzer.datasources.DataSourceError: Induced data error
