zloganalyzer: Critical error, Induced reporting error 
 - exiting application
Stack trace: 
Traceback (most recent call last):
  File "BASE_DIR/loganalyzer/systest/localtests/systesterrormsgtouser.py", line 121, in test_reporter_error_running_app_as_in_verbose_mode
    app.run()
  File "BASE_DIR/loganalyzer/loganalyzercli.py", line 94, in run
    app.run()
  File "BASE_DIR/loganalyzer/application.py", line 23, in run
    reporter.write_report(items)
  File EXTERNAL_SOURCE, in __call__
    return _mock_self._mock_call(*args, **kwargs)
  File EXTERNAL_SOURCE, in _mock_call
    raise effect
loganalyzer.reporters.ReportingError: Induced reporting error
